Workbook

Sheet Register
A1: Disc | B1: Discipline | C1: Seq | D1: Sub-category | E1: Code | F1: Code (new) | G1: Item | H1: Location | I1: Manufacturer | J1: Model | K1: Qty | L1: Qty (raw) | M1: Unit | N1: Drawing ref | O1: Spec status | P1: Approved | Q1: Procured | R1: Spec URL | S1: Folder URL | T1: Notes | U1: Source sheet | V1: Source row | W1: Updated | X1: Updated by | Y1: id (uuid)
A2: 01 | B2: Plaster | C2: 1 | D2: Plaster Finishes | E2: PLEX-01 | G2: Plaster Exterior Walls | H2: Exterior Walls | K2: 1548 | M2: SF | O2: unknown | P2: not_started | Q2: not_started | U2: 01 Plaster | V2: 5 | W2: 46272.719 | X2: system | Y2: 63fff325-be01-5880-913d-ef548c34cbbf
A3: 01 | B3: Plaster | C3: 2 | D3: Plaster Finishes | E3: PLEX-02 | G3: Plaster Exterior Ceilings | H3: Exterior Ceilings | K3: 265 | M3: SF | O3: unknown | P3: not_started | Q3: not_started | U3: 01 Plaster | V3: 6 | W3: 46272.719 | X3: system | Y3: eb7c3874-d7c9-5461-8eb8-f3e95bfb4c2e
A4: 01 | B4: Plaster | C4: 3 | D4: Plaster Finishes | E4: PLIN-01 | G4: Plaster Interior Ceilings | H4: Interior Ceilings | K4: 785 | M4: SF | O4: unknown | P4: not_started | Q4: not_started | U4: 01 Plaster | V4: 7 | W4: 46272.719 | X4: system | Y4: dc7a9b12-9cef-5abf-ac22-02044a8572f3
A5: 01 | B5: Plaster | C5: 4 | D5: Plaster Finishes | E5: PLIN-02 | G5: Plaster Interior Walls | H5: Interior Walls | K5: 396 | M5: SF | O5: unknown | P5: not_started | Q5: not_started | U5: 01 Plaster | V5: 8 | W5: 46272.719 | X5: system | Y5: 04436236-90f5-5e74-8b95-b4053e06b576
A6: 02 | B6: Stone | C6: 5 | D6: Natural Stone | E6: Creme du Provence | G6: Creme du Provence — Column 1-7 cladding (40mm) + Bathroom Vanity legs B3, B4 (20mm) | H6: Column 1-7 cladding (40mm) + Bathroom Vanity legs B3, B4 (20mm) | J6: Millwork schedule | K6: 80 | M6: pcs | O6: unknown | P6: not_started | Q6: not_started | U6: 02 Stone | V6: 5 | W6: 46272.719 | X6: system | Y6: d3fa2585-ee67-5630-a27c-298a1135f6f4
A7: 02 | B7: Stone | C7: 6 | D7: Natural Stone | E7: Mocca Cafe | G7: Mocca Cafe — Bathroom Vanity countertop B1 + cover strips; Nightstands (left and right) | H7: Bathroom Vanity countertop B1 + cover strips; Nightstands (left and right) | J7: Millwork schedule | K7: 15 | M7: pcs | O7: unknown | P7: not_started | Q7: not_started | U7: 02 Stone | V7: 6 | W7: 46272.719 | X7: system | Y7: da864731-593d-51ab-8dc7-62996a28cb6e
A8: 02 | B8: Stone | C8: 7 | D8: Natural Stone | E8: Ocean Black Bricks | G8: Ocean Black Bricks — Entrance platform and steps, entrance inside, bathroom, walk-in closet, bedroom, terrace and step - 12 zones | H8: Entrance platform and steps, entrance inside, bathroom, walk-in closet, bedroom, terrace and step - 12 zones | J8: Floor / pool take-off | K8: 3370 | M8: pcs | O8: unknown | P8: not_started | Q8: not_started | U8: 02 Stone | V8: 7 | W8: 46272.719 | X8: system | Y8: 097b416f-ba33-509b-b2f1-3adeb58dd91d
A9: 02 | B9: Stone | C9: 8 | D9: Natural Stone | E9: Ocean Black Slabs | G9: Ocean Black Slabs — WC and indoor shower pans, small pan, drain covers, threshold strip, rinse showers | H9: WC and indoor shower pans, small pan, drain covers, threshold strip, rinse showers | J9: Floor / pool take-off | K9: 10 | M9: pcs | O9: unknown | P9: not_started | Q9: not_started | U9: 02 Stone | V9: 8 | W9: 46272.719 | X9: system | Y9: 524aab62-1594-5bb1-9de4-0f82f0cda315
A10: 02 | B10: Stone | C10: 9 | D10: Natural Stone | E10: Red Soraya Travertine | G10: Red Soraya Travertine — Mini Bar Cabinetry; Closets Behind the Bed (20mm, built up to 76mm) | H10: Mini Bar Cabinetry; Closets Behind the Bed (20mm, built up to 76mm) | J10: Millwork schedule | K10: 18 | M10: pcs | O10: unknown | P10: not_started | Q10: not_started | U10: 02 Stone | V10: 9 | W10: 46272.719 | X10: system | Y10: 0444f5e6-227e-550d-99f2-f4c9c3dba535
A11: 02 | B11: Stone | C11: 10 | D11: Natural Stone | E11: Sukabumi Slabs | G11: Sukabumi Slabs — Pool floors and stair steps, deep walls and stair risers, shallow walls, through-basin walls | H11: Pool floors and stair steps, deep walls and stair risers, shallow walls, through-basin walls | J11: Floor / pool take-off | K11: 2224 | M11: pcs | O11: unknown | P11: not_started | Q11: not_started | U11: 02 Stone | V11: 10 | W11: 46272.719 | X11: system | Y11: 18bdb000-a22f-54d4-b3e0-813fefc49a0a
A12: 02 | B12: Stone | C12: 11 | D12: Natural Stone | E12: Tundra Beige | G12: Tundra Beige — Outdoor Terrace Bench; Indoor Shower Bench & Towel Hanger (A1-A9); Bathroom Vanity B2; Outdoor Towel Hanger (G1-G5); Day Bed H2/H3; Outdoor Entry Door Bench | H12: Outdoor Terrace Bench; Indoor Shower Bench & Towel Hanger (A1-A9); Bathroom Vanity B2; Outdoor Towel Hanger (G1-G5); Day Bed H2/H3; Outdoor Entry Door Bench | J12: Millwork schedule | K12: 77 | M12: pcs | O12: unknown | P12: not_started | Q12: not_started | U12: 02 Stone | V12: 11 | W12: 46272.719 | X12: system | Y12: c88fa10f-f5e7-59df-aefd-2ba53a3c3ad3
A13: 03 | B13: Doors | C13: 12 | D13: Door Hardware & Ironmongery | E13: 1 | D-01,D-02,D-03 | G13: Concealed door hinge, flush interior doors up to 80/100 kg, brushed copper | H13: W.C., Entrance, Bathroom | I13: Haefele | K13: 18 | M13: no | N13: A11-02/03/04 | O13: not_started | P13: not_started | Q13: not_started | U13: 03 Doors | V13: 5 | W13: 46272.719 | X13: system | Y13: 0c1e53f9-e814-5c98-98ac-e3152fc2ca1b
A14: 03 | B14: Doors | C14: 13 | D14: Door Hardware & Ironmongery | E14: 2 | D-01 | G14: Lever handle set; NE-Black Chrome | H14: Doors | I14: Salto | J14: Salto Standard Line / London Model | K14: 3 | M14: set | N14: A11-02/03/04 | O14: not_started | P14: not_started | Q14: not_started | U14: 03 Doors | V14: 6 | W14: 46272.719 | X14: system | Y14: 6d8b5004-44e8-5779-900a-e5c7788d40b5
A15: 03 | B15: Doors | C15: 14 | D15: Door Hardware & Ironmongery | E15: 2.2 | D-03 | G15: Teak Wood Handle | H15: W.I.C | I15: CBMmart | J15: Exterior Grade Teak Wood Planks and Regular Teak Wood Planks | K15: 3 | N15: A11-02/03/06 | O15: unknown | P15: not_started | Q15: not_started | U15: 03 Doors | V15: 7 | W15: 46272.719 | X15: system | Y15: f8d685bd-db79-5fa4-9fe7-906c87452fa7
A16: 03 | B16: Doors | C16: 15 | D16: Door Hardware & Ironmongery | E16: 3 | D-01 | G16: Electronic lockset | H16: Entrance | I16: Salto | J16: Salto Element Fusion - ANSI | K16: 1 | M16: no | N16: A11-02 | O16: not_started | P16: not_started | Q16: not_started | R16: https://saltosystems.com/en/products/aelement-fusion-ansi/ | U16: 03 Doors | V16: 8 | W16: 46272.719 | X16: system | Y16: e5c50a7b-6c26-5be7-99df-6f2a87e24a41
A17: 03 | B17: Doors | C17: 16 | D17: Door Hardware & Ironmongery | E17: 4 | D-04 | G17: Privacy Thumb Turn | H17: W.C. | I17: Salto | J17: Sargent 8200 Series | K17: 1 | M17: no | N17: A11-04 | O17: not_started | P17: not_started | Q17: not_started | U17: 03 Doors | V17: 9 | W17: 46272.719 | X17: system | Y17: fe3ab175-3e15-5530-8d8f-9ac471b83064
A18: 03 | B18: Doors | C18: 17 | D18: Door Hardware & Ironmongery | E18: 5 | D-01 | G18: Startec door viewer, brushed brass | H18: Entrance | I18: Hafele | J18: Startec 200° 82mm door viewer | K18: 1 | M18: no | N18: A11-02 | O18: not_started | P18: not_started | Q18: not_started | U18: 03 Doors | V18: 10 | W18: 46272.719 | X18: system | Y18: 5f980cf6-0bf0-563c-864b-fc23b24af3d7
A19: 03 | B19: Doors | C19: 18 | D19: Door Hardware & Ironmongery | E19: 6 | D-03 | G19: Sliding door running gear (80/100 8-piece system) | H19: Closet | I19: Hafele | J19: Junior 80/B-Pocket | K19: 1 | M19: set | N19: A11-03 | O19: not_started | P19: not_started | Q19: not_started | U19: 03 Doors | V19: 11 | W19: 46272.719 | X19: system | Y19: c5e3f544-d761-52e7-9730-c6315310e60a
A20: 03 | B20: Doors | C20: 19 | D20: Door Hardware & Ironmongery | E20: 6.1 | S-02 | G20: Sliding door running gear (80/100 8-piece system) | H20: Louver | I20: Hafele | J20: Slido D-Line11 160p | N20: A11-02/03/04 | O20: unknown | P20: not_started | Q20: not_started | R20: https://www.hafele.com/us/en/product/sliding-door-hardware-haefele-slido-d-line11-160p-set/P-01499186/ | U20: 03 Doors | V20: 12 | W20: 46272.719 | X20: system | Y20: 1614b307-a09a-5f8a-be38-42e164967571
A21: 03 | B21: Doors | C21: 20 | D21: Door Hardware & Ironmongery | E21: 7 | D-01 | G21: Automatic Drop Down Seal | H21: All doors | I21: Assa Abloy | J21: Planet X3, RD | K21: 1 | M21: lot | N21: A11-02/03/04 | O21: not_started | P21: not_started | Q21: not_started | R21: https://www.assaabloy.com/ch/en/documents/service/downloads/planet/drop-down-seals/brochure-planet-drop-down-seal-x3.pdf | U21: 03 Doors | V21: 13 | W21: 46272.719 | X21: system | Y21: de94b009-c604-51a6-a197-0a6c9ee74ba4
A22: 03 | B22: Doors | C22: 21 | D22: Door Hardware & Ironmongery | E22: 7.1 | D-02,D-03,D-04 | G22: Sealing rubber frame strips | H22: All doors | I22: Reflect | K22: 3 | M22: lot | N22: A11-02/03/04 | O22: not_started | P22: not_started | Q22: not_started | U22: 03 Doors | V22: 14 | W22: 46272.719 | X22: system | Y22: c8506127-db91-5f2b-b48a-61402a307a83
A23: 03 | B23: Doors | C23: 22 | D23: Wooden Doors (Leaves & Frames) | E23: 1 | S-01 | G23: Bedroom shutter - fixed glass + openable louver + roll blackout | H23: Bedroom | J23: Teak hardwood + tempered glass | K23: 1 | M23: no | N23: A11-02 | O23: in_progress | P23: not_started | Q23: not_started | T23: Finish TBC by MMM. Blackout Lutron R64 = shades (separate scope) | U23: 03 Doors | V23: 15 | W23: 46272.719 | X23: system | Y23: 76400601-f2ad-5e84-8c67-2f7bdca34ef0
A24: 03 | B24: Doors | C24: 23 | D24: Wooden Doors (Leaves & Frames) | E24: 2 | S-02 | G24: Outside living sliding louver doors | H24: Outdoor living | J24: Teak hardwood + tempered glass | K24: 1 | M24: no | N24: A11-02 | O24: in_progress | P24: not_started | Q24: not_started | T24: Sliding louver on track | U24: 03 Doors | V24: 16 | W24: 46272.719 | X24: system | Y24: c057549c-7866-5f36-b38c-cf6caa230349
A25: 03 | B25: Doors | C25: 24 | D25: Wooden Doors (Leaves & Frames) | E25: 3 | D-01 | G25: Entrance door - fixed + swinging | H25: Entrance | J25: Teak hardwood / plywood | K25: 1 | M25: no | N25: A11-02 | O25: in_progress | P25: not_started | Q25: not_started | T25: 6 concealed hinges | U25: 03 Doors | V25: 17 | W25: 46272.719 | X25: system | Y25: b45b5c29-f72b-5331-9a1e-99eec0076478
A26: 03 | B26: Doors | C26: 25 | D26: Wooden Doors (Leaves & Frames) | E26: 4 | D-02 | G26: Bathroom door - swinging | H26: Bathroom | J26: Teak hardwood / plywood | K26: 1 | M26: no | N26: A11-03 | O26: in_progress | P26: not_started | Q26: not_started | U26: 03 Doors | V26: 18 | W26: 46272.719 | X26: system | Y26: bc641b8f-2faf-5cf9-b8fd-2fc792b9ef72
A27: 03 | B27: Doors | C27: 26 | D27: Wooden Doors (Leaves & Frames) | E27: 5 | D-03 | G27: Walk-in closet - sliding louvered doors | H27: Closet | J27: Teak hardwood / plywood | K27: 1 | M27: no | N27: A11-03 | O27: in_progress | P27: not_started | Q27: not_started | U27: 03 Doors | V27: 19 | W27: 46272.719 | X27: system | Y27: cc2d554a-324a-56e3-950a-f7e1098937a7
A28: 03 | B28: Doors | C28: 27 | D28: Wooden Doors (Leaves & Frames) | E28: 6 | D-04 | G28: W.C. door - swinging | H28: W.C. | J28: Teak hardwood / plywood | K28: 1 | M28: no | N28: A11-04 | O28: in_progress | P28: not_started | Q28: not_started | U28: 03 Doors | V28: 20 | W28: 46272.719 | X28: system | Y28: 70ed8b93-9169-58a6-8682-847c3450ef92
A29: 04 | B29: Glazing | C29: 28 | D29: Glass & Framing | E29: 1 | GL.01 | G29: Sliding glazed door into pocket (19 ft 9 in x 9 ft 3-3/4 in) | H29: Bedroom | I29: Assumed ES Windows | J29: Clear glass; structural aluminium, custom anodized | K29: 1 | M29: no | N29: A12-02 | O29: in_progress | P29: not_started | Q29: not_started | U29: 04 Glazing | V29: 5 | W29: 46272.719 | X29: system | Y29: d7e13977-0951-59ba-bb3a-a878e51915ec
A30: 04 | B30: Glazing | C30: 29 | D30: Glass & Framing | E30: 2 | GL.02 | G30: Sliding glazed door into pocket (8 ft 1-1/2 in x 9 ft 3-3/4 in) | H30: Bathroom | I30: Assumed ES Windows | J30: Clear glass; structural aluminium, custom anodized | K30: 1 | M30: no | N30: A12-02 | O30: in_progress | P30: not_started | Q30: not_started | U30: 04 Glazing | V30: 6 | W30: 46272.719 | X30: system | Y30: 25508ff0-f55a-551e-b15b-13a62b0879eb
A31: 04 | B31: Glazing | C31: 30 | D31: Glass & Framing | E31: 3 | GL.03 | G31: Fixed window (4 ft 1 in x 9 ft 3-3/4 in) | H31: Bedroom/entrance/bath | I31: Assumed ES Windows | J31: Clear glass; structural aluminium, custom anodized | K31: 5 | M31: no | N31: A12-02 | O31: in_progress | P31: not_started | Q31: not_started | U31: 04 Glazing | V31: 7 | W31: 46272.719 | X31: system | Y31: 5ceeec99-8640-5491-934a-e50ed60e3aa7
A32: 04 | B32: Glazing | C32: 31 | D32: Glass & Framing | E32: 4 | GL.04 | G32: Fixed window (1 ft 6 in x 9 ft 3-3/4 in) | H32: Bathroom | I32: Assumed ES Windows | J32: Clear glass; structural aluminium, custom anodized | K32: 2 | M32: no | N32: A12-02 | O32: in_progress | P32: not_started | Q32: not_started | U32: 04 Glazing | V32: 8 | W32: 46272.719 | X32: system | Y32: d18ffb9e-8b5a-5a29-b4f3-7f9ded68b680
A33: 04 | B33: Glazing | C33: 32 | D33: Glass & Framing | E33: 5 | GL.05 | G33: Sliding glazed door into pocket (11 ft 11-1/2 in x 9 ft 3-3/4 in) | H33: Bedroom | I33: Assumed ES Windows | J33: Clear glass; structural aluminium, custom anodized | K33: 1 | M33: no | N33: A12-03 | O33: in_progress | P33: not_started | Q33: not_started | U33: 04 Glazing | V33: 9 | W33: 46272.719 | X33: system | Y33: fa0c151a-df9d-5d07-a183-b9750b07c7d2
A34: 04 | B34: Glazing | C34: 33 | D34: Glass & Framing | E34: 6 | GL.06 | G34: Fixed window (small, bathroom) | H34: Bathroom | I34: Assumed ES Windows | J34: Clear glass; structural aluminium, custom anodized | K34: 1 | M34: no | N34: A12-03 | O34: in_progress | P34: not_started | Q34: not_started | U34: 04 Glazing | V34: 10 | W34: 46272.719 | X34: system | Y34: 59c26166-d9ea-5b3a-9e9f-403167669336
A35: 04 | B35: Glazing | C35: 34 | D35: Glass & Framing | E35: 7 | GL.07 | G35: Swinging (hinged) glazed door (2 ft 8 in x 9 ft) | H35: Bathroom | I35: Assumed ES Windows | J35: Clear glass; structural aluminium, custom anodized | K35: 1 | M35: no | N35: A12-03 | O35: in_progress | P35: not_started | Q35: not_started | U35: 04 Glazing | V35: 11 | W35: 46272.719 | X35: system | Y35: cd86c126-568f-51d0-8cdd-097e6feac535
A36: 04 | B36: Glazing | C36: 35 | D36: Glass & Framing | E36: 8 | GL.08 | G36: Swinging (hinged) glazed door (4 ft 1 in x 9 ft 3-3/4 in) | H36: Bathroom | I36: Assumed ES Windows | J36: Clear glass; structural aluminium, custom anodized | K36: 1 | M36: no | N36: A12-03 | O36: in_progress | P36: not_started | Q36: not_started | U36: 04 Glazing | V36: 12 | W36: 46272.719 | X36: system | Y36: 03ad0bc7-6258-59b3-a8c1-41e36e2ab238
A37: 04 | B37: Glazing | C37: 36 | D37: Glazing Hardware & Sliding Gear | E37: 1 | G37: Double handle with invisible integrated lock | H37: Glazed doors | I37: Ottima | K37: 5 | M37: set | N37: A12-02/03 | O37: in_progress | P37: not_started | Q37: not_started | U37: 04 Glazing | V37: 13 | W37: 46272.719 | X37: system | Y37: 4abf8d2d-d6af-5447-99d5-4bc32092e94b
A38: 05 | B38: FF&E | C38: 37 | D38: Fabrics | E38: CUR-01 | G38: Blackout Curtains Aznar FR Twin Face Blackout 063 | H38: Bedroom | I38: Aznar Textile | J38: FR Twin Face Blackout 063 | O38: unknown | P38: not_started | Q38: not_started | U38: 05 FF&E | V38: 5 | W38: 46272.719 | X38: system | Y38: 067f8f61-9800-59f4-97eb-b8b1d0c16797
A39: 05 | B39: FF&E | C39: 38 | D39: Fabrics | E39: UPH-01 | G39: Outdoor Fabric Bikaina YP25004 Ausarta Collection | H39: Bedroom | I39: Designs of the Time | J39: Bikaina YP25004 Ausarta Collection | O39: unknown | P39: not_started | Q39: not_started | U39: 05 FF&E | V39: 6 | W39: 46272.719 | X39: system | Y39: de83dfa7-05ac-5676-bb01-3d4d4f53b282
A40: 05 | B40: FF&E | C40: 39 | D40: Fabrics | E40: UPH-02 | G40: Outdoor Fabric TULUM col. 12 | H40: Bedroom | I40: Guell la madrid | J40: TULUM col. 12 | O40: unknown | P40: not_started | Q40: not_started | U40: 05 FF&E | V40: 7 | W40: 46272.719 | X40: system | Y40: faa74d0f-6985-5272-a8ec-23a5a338bb3f
...

Sheet Coverage
A1: Disc | B1: Discipline | C1: Items | D1: With spec | E1: With folder | F1: Documented | G1: Undocumented | H1: % documented
A2: 01 | B2: Plaster | C2: =COUNTIF(Register!$A:$A,$A2) | D2: =COUNTIFS(Register!$A:$A,$A2,Register!$R:$R,"?*") | E2: =COUNTIFS(Register!$A:$A,$A2,Register!$S:$S,"?*") | F2: =D2+E2-COUNTIFS(Register!$A:$A,$A2,Register!$R:$R,"?*",Register!$S:$S,"?*") | G2: =C2-F2 | H2: =IF(C2=0,"",F2/C2)
A3: 02 | B3: Stone | C3: =COUNTIF(Register!$A:$A,$A3) | D3: =COUNTIFS(Register!$A:$A,$A3,Register!$R:$R,"?*") | E3: =COUNTIFS(Register!$A:$A,$A3,Register!$S:$S,"?*") | F3: =D3+E3-COUNTIFS(Register!$A:$A,$A3,Register!$R:$R,"?*",Register!$S:$S,"?*") | G3: =C3-F3 | H3: =IF(C3=0,"",F3/C3)
A4: 03 | B4: Doors | C4: =COUNTIF(Register!$A:$A,$A4) | D4: =COUNTIFS(Register!$A:$A,$A4,Register!$R:$R,"?*") | E4: =COUNTIFS(Register!$A:$A,$A4,Register!$S:$S,"?*") | F4: =D4+E4-COUNTIFS(Register!$A:$A,$A4,Register!$R:$R,"?*",Register!$S:$S,"?*") | G4: =C4-F4 | H4: =IF(C4=0,"",F4/C4)
A5: 04 | B5: Glazing | C5: =COUNTIF(Register!$A:$A,$A5) | D5: =COUNTIFS(Register!$A:$A,$A5,Register!$R:$R,"?*") | E5: =COUNTIFS(Register!$A:$A,$A5,Register!$S:$S,"?*") | F5: =D5+E5-COUNTIFS(Register!$A:$A,$A5,Register!$R:$R,"?*",Register!$S:$S,"?*") | G5: =C5-F5 | H5: =IF(C5=0,"",F5/C5)
A6: 05 | B6: FF&E | C6: =COUNTIF(Register!$A:$A,$A6) | D6: =COUNTIFS(Register!$A:$A,$A6,Register!$R:$R,"?*") | E6: =COUNTIFS(Register!$A:$A,$A6,Register!$S:$S,"?*") | F6: =D6+E6-COUNTIFS(Register!$A:$A,$A6,Register!$R:$R,"?*",Register!$S:$S,"?*") | G6: =C6-F6 | H6: =IF(C6=0,"",F6/C6)
A7: 06 | B7: Millwork & Joinery | C7: =COUNTIF(Register!$A:$A,$A7) | D7: =COUNTIFS(Register!$A:$A,$A7,Register!$R:$R,"?*") | E7: =COUNTIFS(Register!$A:$A,$A7,Register!$S:$S,"?*") | F7: =D7+E7-COUNTIFS(Register!$A:$A,$A7,Register!$R:$R,"?*",Register!$S:$S,"?*") | G7: =C7-F7 | H7: =IF(C7=0,"",F7/C7)
A8: 07 | B8: Plumbing Systems | C8: =COUNTIF(Register!$A:$A,$A8) | D8: =COUNTIFS(Register!$A:$A,$A8,Register!$R:$R,"?*") | E8: =COUNTIFS(Register!$A:$A,$A8,Register!$S:$S,"?*") | F8: =D8+E8-COUNTIFS(Register!$A:$A,$A8,Register!$R:$R,"?*",Register!$S:$S,"?*") | G8: =C8-F8 | H8: =IF(C8=0,"",F8/C8)
A9: 08 | B9: Plumbing Equipment | C9: =COUNTIF(Register!$A:$A,$A9) | D9: =COUNTIFS(Register!$A:$A,$A9,Register!$R:$R,"?*") | E9: =COUNTIFS(Register!$A:$A,$A9,Register!$S:$S,"?*") | F9: =D9+E9-COUNTIFS(Register!$A:$A,$A9,Register!$R:$R,"?*",Register!$S:$S,"?*") | G9: =C9-F9 | H9: =IF(C9=0,"",F9/C9)
A10: 09 | B10: Pool & Water Features | C10: =COUNTIF(Register!$A:$A,$A10) | D10: =COUNTIFS(Register!$A:$A,$A10,Register!$R:$R,"?*") | E10: =COUNTIFS(Register!$A:$A,$A10,Register!$S:$S,"?*") | F10: =D10+E10-COUNTIFS(Register!$A:$A,$A10,Register!$R:$R,"?*",Register!$S:$S,"?*") | G10: =C10-F10 | H10: =IF(C10=0,"",F10/C10)
A11: 10 | B11: Electrical | C11: =COUNTIF(Register!$A:$A,$A11) | D11: =COUNTIFS(Register!$A:$A,$A11,Register!$R:$R,"?*") | E11: =COUNTIFS(Register!$A:$A,$A11,Register!$S:$S,"?*") | F11: =D11+E11-COUNTIFS(Register!$A:$A,$A11,Register!$R:$R,"?*",Register!$S:$S,"?*") | G11: =C11-F11 | H11: =IF(C11=0,"",F11/C11)
A12: 11 | B12: Low Voltage & ICT | C12: =COUNTIF(Register!$A:$A,$A12) | D12: =COUNTIFS(Register!$A:$A,$A12,Register!$R:$R,"?*") | E12: =COUNTIFS(Register!$A:$A,$A12,Register!$S:$S,"?*") | F12: =D12+E12-COUNTIFS(Register!$A:$A,$A12,Register!$R:$R,"?*",Register!$S:$S,"?*") | G12: =C12-F12 | H12: =IF(C12=0,"",F12/C12)
A13: 12 | B13: Lighting | C13: =COUNTIF(Register!$A:$A,$A13) | D13: =COUNTIFS(Register!$A:$A,$A13,Register!$R:$R,"?*") | E13: =COUNTIFS(Register!$A:$A,$A13,Register!$S:$S,"?*") | F13: =D13+E13-COUNTIFS(Register!$A:$A,$A13,Register!$R:$R,"?*",Register!$S:$S,"?*") | G13: =C13-F13 | H13: =IF(C13=0,"",F13/C13)
A14: 13 | B14: HVAC & Mechanical | C14: =COUNTIF(Register!$A:$A,$A14) | D14: =COUNTIFS(Register!$A:$A,$A14,Register!$R:$R,"?*") | E14: =COUNTIFS(Register!$A:$A,$A14,Register!$S:$S,"?*") | F14: =D14+E14-COUNTIFS(Register!$A:$A,$A14,Register!$R:$R,"?*",Register!$S:$S,"?*") | G14: =C14-F14 | H14: =IF(C14=0,"",F14/C14)
B15: TOTAL | C15: =SUM(C2:C14) | D15: =SUM(D2:D14) | E15: =SUM(E2:E14) | F15: =SUM(F2:F14) | G15: =SUM(G2:G14) | H15: =IF(C15=0,"",F15/C15)

Sheet Gaps
A1: Disc | B1: Discipline | C1: Sub-category | D1: Code | E1: Item | F1: Location | G1: Manufacturer | H1: Model | I1: Qty | J1: Unit | K1: Drawing ref | L1: Spec status | M1: Notes
A2: 01 | B2: Plaster | C2: Plaster Finishes | D2: PLEX-01 | E2: Plaster Exterior Walls | F2: Exterior Walls | I2: 1548 | J2: SF | L2: unknown
A3: 01 | B3: Plaster | C3: Plaster Finishes | D3: PLEX-02 | E3: Plaster Exterior Ceilings | F3: Exterior Ceilings | I3: 265 | J3: SF | L3: unknown
A4: 01 | B4: Plaster | C4: Plaster Finishes | D4: PLIN-01 | E4: Plaster Interior Ceilings | F4: Interior Ceilings | I4: 785 | J4: SF | L4: unknown
A5: 01 | B5: Plaster | C5: Plaster Finishes | D5: PLIN-02 | E5: Plaster Interior Walls | F5: Interior Walls | I5: 396 | J5: SF | L5: unknown
A6: 02 | B6: Stone | C6: Natural Stone | D6: Creme du Provence | E6: Creme du Provence — Column 1-7 cladding (40mm) + Bathroom Vanity legs B3, B4 (20mm) | F6: Column 1-7 cladding (40mm) + Bathroom Vanity legs B3, B4 (20mm) | H6: Millwork schedule | I6: 80 | J6: pcs | L6: unknown
A7: 02 | B7: Stone | C7: Natural Stone | D7: Mocca Cafe | E7: Mocca Cafe — Bathroom Vanity countertop B1 + cover strips; Nightstands (left and right) | F7: Bathroom Vanity countertop B1 + cover strips; Nightstands (left and right) | H7: Millwork schedule | I7: 15 | J7: pcs | L7: unknown
A8: 02 | B8: Stone | C8: Natural Stone | D8: Ocean Black Bricks | E8: Ocean Black Bricks — Entrance platform and steps, entrance inside, bathroom, walk-in closet, bedroom, terrace and step - 12 zones | F8: Entrance platform and steps, entrance inside, bathroom, walk-in closet, bedroom, terrace and step - 12 zones | H8: Floor / pool take-off | I8: 3370 | J8: pcs | L8: unknown
A9: 02 | B9: Stone | C9: Natural Stone | D9: Ocean Black Slabs | E9: Ocean Black Slabs — WC and indoor shower pans, small pan, drain covers, threshold strip, rinse showers | F9: WC and indoor shower pans, small pan, drain covers, threshold strip, rinse showers | H9: Floor / pool take-off | I9: 10 | J9: pcs | L9: unknown
A10: 02 | B10: Stone | C10: Natural Stone | D10: Red Soraya Travertine | E10: Red Soraya Travertine — Mini Bar Cabinetry; Closets Behind the Bed (20mm, built up to 76mm) | F10: Mini Bar Cabinetry; Closets Behind the Bed (20mm, built up to 76mm) | H10: Millwork schedule | I10: 18 | J10: pcs | L10: unknown
A11: 02 | B11: Stone | C11: Natural Stone | D11: Sukabumi Slabs | E11: Sukabumi Slabs — Pool floors and stair steps, deep walls and stair risers, shallow walls, through-basin walls | F11: Pool floors and stair steps, deep walls and stair risers, shallow walls, through-basin walls | H11: Floor / pool take-off | I11: 2224 | J11: pcs | L11: unknown
A12: 02 | B12: Stone | C12: Natural Stone | D12: Tundra Beige | E12: Tundra Beige — Outdoor Terrace Bench; Indoor Shower Bench & Towel Hanger (A1-A9); Bathroom Vanity B2; Outdoor Towel Hanger (G1-G5); Day Bed H2/H3; Outdoor Entry Door Bench | F12: Outdoor Terrace Bench; Indoor Shower Bench & Towel Hanger (A1-A9); Bathroom Vanity B2; Outdoor Towel Hanger (G1-G5); Day Bed H2/H3; Outdoor Entry Door Bench | H12: Millwork schedule | I12: 77 | J12: pcs | L12: unknown
A13: 03 | B13: Doors | C13: Door Hardware & Ironmongery | D13: 1 | D-01,D-02,D-03 | E13: Concealed door hinge, flush interior doors up to 80/100 kg, brushed copper | F13: W.C., Entrance, Bathroom | G13: Haefele | I13: 18 | J13: no | K13: A11-02/03/04 | L13: not_started
A14: 03 | B14: Doors | C14: Door Hardware & Ironmongery | D14: 2 | D-01 | E14: Lever handle set; NE-Black Chrome | F14: Doors | G14: Salto | H14: Salto Standard Line / London Model | I14: 3 | J14: set | K14: A11-02/03/04 | L14: not_started
A15: 03 | B15: Doors | C15: Door Hardware & Ironmongery | D15: 2.2 | D-03 | E15: Teak Wood Handle | F15: W.I.C | G15: CBMmart | H15: Exterior Grade Teak Wood Planks and Regular Teak Wood Planks | I15: 3 | K15: A11-02/03/06 | L15: unknown
A16: 03 | B16: Doors | C16: Door Hardware & Ironmongery | D16: 4 | D-04 | E16: Privacy Thumb Turn | F16: W.C. | G16: Salto | H16: Sargent 8200 Series | I16: 1 | J16: no | K16: A11-04 | L16: not_started
A17: 03 | B17: Doors | C17: Door Hardware & Ironmongery | D17: 5 | D-01 | E17: Startec door viewer, brushed brass | F17: Entrance | G17: Hafele | H17: Startec 200° 82mm door viewer | I17: 1 | J17: no | K17: A11-02 | L17: not_started
A18: 03 | B18: Doors | C18: Door Hardware & Ironmongery | D18: 6 | D-03 | E18: Sliding door running gear (80/100 8-piece system) | F18: Closet | G18: Hafele | H18: Junior 80/B-Pocket | I18: 1 | J18: set | K18: A11-03 | L18: not_started
A19: 03 | B19: Doors | C19: Door Hardware & Ironmongery | D19: 7.1 | D-02,D-03,D-04 | E19: Sealing rubber frame strips | F19: All doors | G19: Reflect | I19: 3 | J19: lot | K19: A11-02/03/04 | L19: not_started
A20: 03 | B20: Doors | C20: Wooden Doors (Leaves & Frames) | D20: 1 | S-01 | E20: Bedroom shutter - fixed glass + openable louver + roll blackout | F20: Bedroom | H20: Teak hardwood + tempered glass | I20: 1 | J20: no | K20: A11-02 | L20: in_progress | M20: Finish TBC by MMM. Blackout Lutron R64 = shades (separate scope)
A21: 03 | B21: Doors | C21: Wooden Doors (Leaves & Frames) | D21: 2 | S-02 | E21: Outside living sliding louver doors | F21: Outdoor living | H21: Teak hardwood + tempered glass | I21: 1 | J21: no | K21: A11-02 | L21: in_progress | M21: Sliding louver on track
A22: 03 | B22: Doors | C22: Wooden Doors (Leaves & Frames) | D22: 3 | D-01 | E22: Entrance door - fixed + swinging | F22: Entrance | H22: Teak hardwood / plywood | I22: 1 | J22: no | K22: A11-02 | L22: in_progress | M22: 6 concealed hinges
A23: 03 | B23: Doors | C23: Wooden Doors (Leaves & Frames) | D23: 4 | D-02 | E23: Bathroom door - swinging | F23: Bathroom | H23: Teak hardwood / plywood | I23: 1 | J23: no | K23: A11-03 | L23: in_progress
A24: 03 | B24: Doors | C24: Wooden Doors (Leaves & Frames) | D24: 5 | D-03 | E24: Walk-in closet - sliding louvered doors | F24: Closet | H24: Teak hardwood / plywood | I24: 1 | J24: no | K24: A11-03 | L24: in_progress
A25: 03 | B25: Doors | C25: Wooden Doors (Leaves & Frames) | D25: 6 | D-04 | E25: W.C. door - swinging | F25: W.C. | H25: Teak hardwood / plywood | I25: 1 | J25: no | K25: A11-04 | L25: in_progress
A26: 04 | B26: Glazing | C26: Glass & Framing | D26: 1 | GL.01 | E26: Sliding glazed door into pocket (19 ft 9 in x 9 ft 3-3/4 in) | F26: Bedroom | G26: Assumed ES Windows | H26: Clear glass; structural aluminium, custom anodized | I26: 1 | J26: no | K26: A12-02 | L26: in_progress
A27: 04 | B27: Glazing | C27: Glass & Framing | D27: 2 | GL.02 | E27: Sliding glazed door into pocket (8 ft 1-1/2 in x 9 ft 3-3/4 in) | F27: Bathroom | G27: Assumed ES Windows | H27: Clear glass; structural aluminium, custom anodized | I27: 1 | J27: no | K27: A12-02 | L27: in_progress
A28: 04 | B28: Glazing | C28: Glass & Framing | D28: 3 | GL.03 | E28: Fixed window (4 ft 1 in x 9 ft 3-3/4 in) | F28: Bedroom/entrance/bath | G28: Assumed ES Windows | H28: Clear glass; structural aluminium, custom anodized | I28: 5 | J28: no | K28: A12-02 | L28: in_progress
A29: 04 | B29: Glazing | C29: Glass & Framing | D29: 4 | GL.04 | E29: Fixed window (1 ft 6 in x 9 ft 3-3/4 in) | F29: Bathroom | G29: Assumed ES Windows | H29: Clear glass; structural aluminium, custom anodized | I29: 2 | J29: no | K29: A12-02 | L29: in_progress
A30: 04 | B30: Glazing | C30: Glass & Framing | D30: 5 | GL.05 | E30: Sliding glazed door into pocket (11 ft 11-1/2 in x 9 ft 3-3/4 in) | F30: Bedroom | G30: Assumed ES Windows | H30: Clear glass; structural aluminium, custom anodized | I30: 1 | J30: no | K30: A12-03 | L30: in_progress
A31: 04 | B31: Glazing | C31: Glass & Framing | D31: 6 | GL.06 | E31: Fixed window (small, bathroom) | F31: Bathroom | G31: Assumed ES Windows | H31: Clear glass; structural aluminium, custom anodized | I31: 1 | J31: no | K31: A12-03 | L31: in_progress
A32: 04 | B32: Glazing | C32: Glass & Framing | D32: 7 | GL.07 | E32: Swinging (hinged) glazed door (2 ft 8 in x 9 ft) | F32: Bathroom | G32: Assumed ES Windows | H32: Clear glass; structural aluminium, custom anodized | I32: 1 | J32: no | K32: A12-03 | L32: in_progress
A33: 04 | B33: Glazing | C33: Glass & Framing | D33: 8 | GL.08 | E33: Swinging (hinged) glazed door (4 ft 1 in x 9 ft 3-3/4 in) | F33: Bathroom | G33: Assumed ES Windows | H33: Clear glass; structural aluminium, custom anodized | I33: 1 | J33: no | K33: A12-03 | L33: in_progress
A34: 04 | B34: Glazing | C34: Glazing Hardware & Sliding Gear | D34: 1 | E34: Double handle with invisible integrated lock | F34: Glazed doors | G34: Ottima | I34: 5 | J34: set | K34: A12-02/03 | L34: in_progress
A35: 05 | B35: FF&E | C35: Fabrics | D35: CUR-01 | E35: Blackout Curtains Aznar FR Twin Face Blackout 063 | F35: Bedroom | G35: Aznar Textile | H35: FR Twin Face Blackout 063 | L35: unknown
A36: 05 | B36: FF&E | C36: Fabrics | D36: UPH-01 | E36: Outdoor Fabric Bikaina YP25004 Ausarta Collection | F36: Bedroom | G36: Designs of the Time | H36: Bikaina YP25004 Ausarta Collection | L36: unknown
A37: 05 | B37: FF&E | C37: Fabrics | D37: UPH-02 | E37: Outdoor Fabric TULUM col. 12 | F37: Bedroom | G37: Guell la madrid | H37: TULUM col. 12 | L37: unknown
A38: 05 | B38: FF&E | C38: Fabrics | D38: CUR-02 | E38: Stripe Sheer plum | F38: Bedroom | G38: HOLLAND AND SHERRY | H38: 75360 Osian Collection 97501/CB | L38: unknown
A39: 05 | B39: FF&E | C39: Fabrics | D39: UPH-03 | E39: In-Outdoor Fabric Tan Tan 60482 Col. 13093 | F39: Bedroom | G39: Maria Flora | H39: Tan Tan 60482 Col. 13093 | L39: unknown
A40: 05 | B40: FF&E | C40: Fabrics | D40: UPH-04 | E40: In-Outdoor Fabric Crisalide 60724 Col. 131 | F40: Outdoor Living / Outdoor terrace (uncovered) | G40: Maria Flora | H40: Crisalide 60724 Col. 131 | L40: unknown
...

Sheet About
A1: GP1-MUR Material Register
A3: Exported | B3: 2026-09-08 15:54 UTC
A4: Source | B4: Supabase project iygkonfuyslvgezgofby, schema gp1
A5: Tables | B5: gp1.register_item (199 rows) and the view gp1.register_coverage
A6: Read as | B6: anon over PostgREST - anything row level security hides is not here
A7: Rows last touched | B7: 2026-09-07 17:15:16 UTC
A9: Sheets
A10: Register | B10: Every row and every column of gp1.register_item, ordered by discipline then seq. Filters on, header frozen.
A11: Coverage | B11: Documentation coverage per discipline. The numbers are COUNTIFS over the Register sheet, so they follow your edits.
A12: Gaps | B12: The 128 items with neither a spec URL nor a folder URL - the work list.
A14: Reading the data
A15: Documented | B15: spec_url or folder_url is set. Nothing carries a folder_url yet, so today documented means has a datasheet.
A16: Code | B16: code_tag is verbatim from the source workbook and is NOT unique - Cable appears 8 times. The uuid is the identity.
A17: Qty (raw) | B17: Holds the original text when a quantity would not parse as a number. Empty across the board right now.
A18: Spec status | B18: complete / in_progress / not_started / unknown
A19: Approved | B19: not_started / submitted / approved / rejected / unknown
A20: Procured | B20: not_started / quoted / ordered / delivered / installed / unknown
A22: Round trip | B22: This is an export, not a link. Editing here does not change the database - the register app writes back, or re-import.
